<?xml version="1.0"?>
<robot xmlns:xacro="http://www.ros.org/wiki/xacro">
        
    <xacro:property name="camera_length" value="0.01"/>
    <xacro:property name="camera_width" value="0.1"/>
    <xacro:property name="camera_height" value="0.05"/>

     <link name="camera_link">
        <visual>
            <geometry>
                <box size="${camera_length} ${camera_width} ${camera_height}"/>
            </geometry>
            <material name="grey"/>
        </visual>
        <collision>
            <geometry>
                <box size="${camera_length} ${camera_width} ${camera_height}"/>
            </geometry>
        </collision>
        <xacro:box_inertia m="0.1" l="${camera_length}" w="${camera_width}" h="${camera_height}"
                           xyz="0 0 0" rpy="0 0 0"/>

     </link>

     <joint name="base_camera_joint" type="revolute">
     
         <parent link="arm_base_link4"/>
         <child link="camera_link" />
         <origin xyz="0 0 0.07 " rpy="0 ${pi*2} 0" />
         <axis xyz="0 -1 0" />
        <limit lower="0" upper="${pi*2}" effort="200" velocity="100" />
        <dynamics friction="3.05" damping="1.0" />
     </joint>
     
     <!--<joint name="base_camera_joint" type="fixed">
     
         <parent link="hand_link"/>
         <child link="camera_link" />
         <origin xyz="0.02 0 0.3" rpy="0 0 0" /> 
     
     </joint>-->
     
     <link name="camera_link_optical">
     </link>

    <joint name="camera_optical_joint" type="fixed">
       <!-- these values have to be these values otherwise the gazebo camera
        image won't be aligned properly with the frame it is supposedly
        originating from -->
        <origin xyz="0 0 0" rpy="${-pi/2} 0 ${-pi/2}"/>
        <parent link="camera_link"/>
        <child link="camera_link_optical"/>
    </joint>

     
     <gazebo reference="camera_link">
     <material>Gazebo/ZincYellow</material> 
     <sensor name="camera_sensor" type="camera">
     <pose>0 0 0 0 0 0</pose>
     <visualize>true</visualize>
     <update_rate>10.0</update_rate> 

      <camera>
       <horizontal_fov>1.3962634</horizontal_fov> 
       <image>
         <width>1280</width>         
         <height>720</height>
         <format>R8G8B8</format>   
       </image>
      </camera>

     <plugin name="camera_controller" filename="libgazebo_ros_camera.so">
      <frame_name>camera_link_optical</frame_name> 
     </plugin>
     </sensor>
    </gazebo>
 <!--
     <gazebo reference="camera_link">
        <material>Gazebo/ZincYellow</material> 
        <sensor name="camera_sensor" type="camera">
          <pose>0 0 0 0 0 0</pose>
          <visualize>true</visualize>
          <update_rate>10.0</update_rate>
            <plugin name="camera_controller" filename="libgazebo_ros_camera.so">
                <frame_name>camera_link_optical</frame_name> 
            </plugin>

        </sensor>
         

     </gazebo>-->

</robot>
